[ 2025-06-23 17:41:29,411 ] 97 werkzeug - INFO - [31m[1mWARNING: This is a development server. Do not use it in a production deployment. Use a production WSGI server instead.[0m
 * Running on all addresses (0.0.0.0)
 * Running on http://127.0.0.1:5000
 * Running on http://192.168.1.3:5000
[ 2025-06-23 17:41:29,412 ] 97 werkzeug - INFO - [33mPress CTRL+C to quit[0m
[ 2025-06-23 17:41:34,846 ] 838 app - ERROR - Exception on /predictdata [POST]
Traceback (most recent call last):
  File "D:\Tugas\MLOps_course\mlproject\src\utils.py", line 61, in load_object
    with open(file_path, "rb") as file_obj:
FileNotFoundError: [Errno 2] No such file or directory: 'artifacts\\preprocessor.pkl'

During handling of the above exception, another exception occurred:

Traceback (most recent call last):
  File "D:\Tugas\MLOps_course\mlproject\src\pipeline\predict_pipeline.py", line 18, in predict
    preprocessor = load_object(file_path=preprocessor_path)
  File "D:\Tugas\MLOps_course\mlproject\src\utils.py", line 65, in load_object
    raise CustomException(e, sys)
src.exception.CustomException: Error occured in python script name [D:\Tugas\MLOps_course\mlproject\src\utils.py] line number [61] error message[[Errno 2] No such file or directory: 'artifacts\\preprocessor.pkl']

During handling of the above exception, another exception occurred:

Traceback (most recent call last):
  File "C:\Users\USER\AppData\Local\Programs\Python\Python310\lib\site-packages\flask\app.py", line 1473, in wsgi_app
    response = self.full_dispatch_request()
  File "C:\Users\USER\AppData\Local\Programs\Python\Python310\lib\site-packages\flask\app.py", line 882, in full_dispatch_request
    rv = self.handle_user_exception(e)
  File "C:\Users\USER\AppData\Local\Programs\Python\Python310\lib\site-packages\flask\app.py", line 880, in full_dispatch_request
    rv = self.dispatch_request()
  File "C:\Users\USER\AppData\Local\Programs\Python\Python310\lib\site-packages\flask\app.py", line 865, in dispatch_request
    return self.ensure_sync(self.view_functions[rule.endpoint])(**view_args)  # type: ignore[no-any-return]
  File "D:\Tugas\MLOps_course\mlproject\app.py", line 40, in predict_datapoint
    results = predict_pipeline.predict(pred_df)
  File "D:\Tugas\MLOps_course\mlproject\src\pipeline\predict_pipeline.py", line 25, in predict
    raise CustomException(e, sys)
src.exception.CustomException: Error occured in python script name [D:\Tugas\MLOps_course\mlproject\src\pipeline\predict_pipeline.py] line number [18] error message[Error occured in python script name [D:\Tugas\MLOps_course\mlproject\src\utils.py] line number [61] error message[[Errno 2] No such file or directory: 'artifacts\\preprocessor.pkl']]
[ 2025-06-23 17:41:34,847 ] 97 werkzeug - INFO - 127.0.0.1 - - [23/Jun/2025 17:41:34] "[35m[1mPOST /predictdata HTTP/1.1[0m" 500 -
[ 2025-06-23 17:41:36,895 ] 97 werkzeug - INFO - 127.0.0.1 - - [23/Jun/2025 17:41:36] "GET /predictdata HTTP/1.1" 200 -
[ 2025-06-23 17:41:43,552 ] 838 app - ERROR - Exception on /predictdata [POST]
Traceback (most recent call last):
  File "D:\Tugas\MLOps_course\mlproject\src\utils.py", line 61, in load_object
    with open(file_path, "rb") as file_obj:
FileNotFoundError: [Errno 2] No such file or directory: 'artifacts\\preprocessor.pkl'

During handling of the above exception, another exception occurred:

Traceback (most recent call last):
  File "D:\Tugas\MLOps_course\mlproject\src\pipeline\predict_pipeline.py", line 18, in predict
    preprocessor = load_object(file_path=preprocessor_path)
  File "D:\Tugas\MLOps_course\mlproject\src\utils.py", line 65, in load_object
    raise CustomException(e, sys)
src.exception.CustomException: Error occured in python script name [D:\Tugas\MLOps_course\mlproject\src\utils.py] line number [61] error message[[Errno 2] No such file or directory: 'artifacts\\preprocessor.pkl']

During handling of the above exception, another exception occurred:

Traceback (most recent call last):
  File "C:\Users\USER\AppData\Local\Programs\Python\Python310\lib\site-packages\flask\app.py", line 1473, in wsgi_app
    response = self.full_dispatch_request()
  File "C:\Users\USER\AppData\Local\Programs\Python\Python310\lib\site-packages\flask\app.py", line 882, in full_dispatch_request
    rv = self.handle_user_exception(e)
  File "C:\Users\USER\AppData\Local\Programs\Python\Python310\lib\site-packages\flask\app.py", line 880, in full_dispatch_request
    rv = self.dispatch_request()
  File "C:\Users\USER\AppData\Local\Programs\Python\Python310\lib\site-packages\flask\app.py", line 865, in dispatch_request
    return self.ensure_sync(self.view_functions[rule.endpoint])(**view_args)  # type: ignore[no-any-return]
  File "D:\Tugas\MLOps_course\mlproject\app.py", line 40, in predict_datapoint
    results = predict_pipeline.predict(pred_df)
  File "D:\Tugas\MLOps_course\mlproject\src\pipeline\predict_pipeline.py", line 25, in predict
    raise CustomException(e, sys)
src.exception.CustomException: Error occured in python script name [D:\Tugas\MLOps_course\mlproject\src\pipeline\predict_pipeline.py] line number [18] error message[Error occured in python script name [D:\Tugas\MLOps_course\mlproject\src\utils.py] line number [61] error message[[Errno 2] No such file or directory: 'artifacts\\preprocessor.pkl']]
[ 2025-06-23 17:41:43,553 ] 97 werkzeug - INFO - 127.0.0.1 - - [23/Jun/2025 17:41:43] "[35m[1mPOST /predictdata HTTP/1.1[0m" 500 -
